[2024-06-16T04:16:58.049-0300] {local_task_job_runner.py:120} INFO - ::group::Pre task execution logs
[2024-06-16T04:16:58.083-0300] {taskinstance.py:2076} INFO - Dependencies all met for dep_context=non-requeueable deps ti=<TaskInstance: indicium_challenge.extracts.csv manual__2024-06-16T07:16:48.576976+00:00 [queued]>
[2024-06-16T04:16:58.092-0300] {taskinstance.py:2076} INFO - Dependencies all met for dep_context=requeueable deps ti=<TaskInstance: indicium_challenge.extracts.csv manual__2024-06-16T07:16:48.576976+00:00 [queued]>
[2024-06-16T04:16:58.092-0300] {taskinstance.py:2306} INFO - Starting attempt 1 of 1
[2024-06-16T04:16:58.114-0300] {taskinstance.py:2330} INFO - Executing <Task(DockerOperator): extracts.csv> on 2024-06-16 07:16:48.576976+00:00
[2024-06-16T04:16:58.136-0300] {standard_task_runner.py:63} INFO - Started process 38756 to run task
[2024-06-16T04:16:58.168-0300] {standard_task_runner.py:90} INFO - Running: ['airflow', 'tasks', 'run', 'indicium_challenge', 'extracts.csv', 'manual__2024-06-16T07:16:48.576976+00:00', '--job-id', '13', '--raw', '--subdir', 'DAGS_FOLDER/extract_data.py', '--cfg-path', '/tmp/tmpruxuhvt5']
[2024-06-16T04:16:58.170-0300] {standard_task_runner.py:91} INFO - Job 13: Subtask extracts.csv
[2024-06-16T04:16:58.215-0300] {task_command.py:426} INFO - Running <TaskInstance: indicium_challenge.extracts.csv manual__2024-06-16T07:16:48.576976+00:00 [running]> on host LAPTOP-6NHM3R4R.
[2024-06-16T04:16:58.279-0300] {taskinstance.py:2648} INFO - Exporting env vars: AIRFLOW_CTX_DAG_OWNER='airflow' AIRFLOW_CTX_DAG_ID='indicium_challenge' AIRFLOW_CTX_TASK_ID='extracts.csv' AIRFLOW_CTX_EXECUTION_DATE='2024-06-16T07:16:48.576976+00:00' AIRFLOW_CTX_TRY_NUMBER='1' AIRFLOW_CTX_DAG_RUN_ID='manual__2024-06-16T07:16:48.576976+00:00'
[2024-06-16T04:16:58.281-0300] {taskinstance.py:430} INFO - ::endgroup::
[2024-06-16T04:16:58.287-0300] {docker.py:157} ERROR - Failed to establish connection to Docker host unix://var/run/docker.sock: Error while fetching server API version: ('Connection aborted.', FileNotFoundError(2, 'No such file or directory'))
[2024-06-16T04:16:58.287-0300] {taskinstance.py:441} INFO - ::group::Post task execution logs
[2024-06-16T04:16:58.292-0300] {taskinstance.py:2905} ERROR - Task failed with exception
Traceback (most recent call last):
  File "/home/maira/.local/lib/python3.10/site-packages/airflow/models/taskinstance.py", line 465, in _execute_task
    result = _execute_callable(context=context, **execute_callable_kwargs)
  File "/home/maira/.local/lib/python3.10/site-packages/airflow/models/taskinstance.py", line 432, in _execute_callable
    return execute_callable(context=context, **execute_callable_kwargs)
  File "/home/maira/.local/lib/python3.10/site-packages/airflow/models/baseoperator.py", line 401, in wrapper
    return func(self, *args, **kwargs)
  File "/home/maira/.local/lib/python3.10/site-packages/airflow/providers/docker/operators/docker.py", line 492, in execute
    if self.force_pull or not self.cli.images(name=self.image):
  File "/home/maira/.local/lib/python3.10/site-packages/airflow/providers/docker/operators/docker.py", line 362, in cli
    return self.hook.api_client
  File "/usr/lib/python3.10/functools.py", line 981, in __get__
    val = self.func(instance)
  File "/home/maira/.local/lib/python3.10/site-packages/airflow/providers/docker/hooks/docker.py", line 161, in api_client
    raise AirflowException("Failed to establish connection to any given Docker hosts.")
airflow.exceptions.AirflowException: Failed to establish connection to any given Docker hosts.
[2024-06-16T04:16:58.300-0300] {taskinstance.py:1206} INFO - Marking task as FAILED. dag_id=indicium_challenge, task_id=extracts.csv, run_id=manual__2024-06-16T07:16:48.576976+00:00, execution_date=20240616T071648, start_date=20240616T071658, end_date=20240616T071658
[2024-06-16T04:16:58.317-0300] {standard_task_runner.py:110} ERROR - Failed to execute job 13 for task extracts.csv (Failed to establish connection to any given Docker hosts.; 38756)
[2024-06-16T04:16:58.341-0300] {local_task_job_runner.py:240} INFO - Task exited with return code 1
[2024-06-16T04:16:58.357-0300] {taskinstance.py:3503} INFO - 0 downstream tasks scheduled from follow-on schedule check
[2024-06-16T04:16:58.369-0300] {local_task_job_runner.py:222} INFO - ::endgroup::
