[2024-06-16T21:31:49.196-0300] {scheduler_job_runner.py:843} ERROR - Executor reports task instance <TaskInstance: indicium_challenge.extracts.csv scheduled__2024-06-16T00:00:00+00:00 [queued]> finished (failed) although the task says it's queued. (Info: None) Was the task killed externally?
